<?xml version="1.0" ?>
<robot name="quadro" xmlns:xacro="http://www.ros.org/wiki/xacro">
<!-- Generated using onshape-to-robot -->
<!-- Onshape https://cad.onshape.com/documents/bab46d1a02d1cb675f27d5f3/w/8adfe612a59991dc5461d3ee/e/70f9c16cd5f973469d7c85a0 -->
  <!-- Link back_plate -->
  <link name="back_plate">
    <inertial>
      <origin xyz="-3.82601e-05 -0.00496654 -0.00528261" rpy="0 0 0"/>
      <mass value="2.59053"/>
      <inertia ixx="0.0255846" ixy="-4.15339e-05" ixz="4e-12" iyy="0.00872593" iyz="-0.000207516" izz="0.0313278"/>
    </inertial>
    <!-- Part back_plate_parts -->
    <visual>
      <origin xyz="-3.82601e-05 -0.00496654 -0.00528261" rpy="0 -0 0"/>
      <geometry>
        <mesh filename="file://$(find quadruped_control)/description/assets/back_plate_visual.stl"/>
      </geometry>
      <material name="back_plate_parts_material">
        <color rgba="0.67735 0.643034 0.48069 1"/>
      </material>
    </visual>
    <collision>
      <origin xyz="-3.82601e-05 -0.00496654 -0.00528261" rpy="0 -0 0"/>
      <geometry>
        <mesh filename="file://$(find quadruped_control)/description/assets/back_plate_collision.stl"/>
      </geometry>
    </collision>
  </link>
  <!-- Link shaft -->
  <link name="shaft">
    <inertial>
      <origin xyz="-0.00474046 0.00407901 -0.0612986" rpy="0 0 0"/>
      <mass value="0.452938"/>
      <inertia ixx="0.000550761" ixy="-6.00381e-05" ixz="-1.13918e-05" iyy="0.00055728" iyz="1.18589e-05" izz="0.000239291"/>
    </inertial>
    <!-- Part shaft_parts -->
    <visual>
      <origin xyz="-0.00474046 0.00407901 -0.0612986" rpy="-1.5708 0 -3.14159"/>
      <geometry>
        <mesh filename="file://$(find quadruped_control)/description/assets/shaft_visual.stl"/>
      </geometry>
      <material name="shaft_parts_material">
        <color rgba="0.556109 0.556109 0.556109 1"/>
      </material>
    </visual>
    <collision>
      <origin xyz="-0.00474046 0.00407901 -0.0612986" rpy="-1.5708 0 -3.14159"/>
      <geometry>
        <mesh filename="file://$(find quadruped_control)/description/assets/shaft_collision.stl"/>
      </geometry>
    </collision>
  </link>
  <!-- Link shaft_2 -->
  <link name="shaft_2">
    <inertial>
      <origin xyz="0.00931177 -0.00187407 -0.0491985" rpy="0 0 0"/>
      <mass value="0.524841"/>
      <inertia ixx="0.000439148" ixy="6.14395e-05" ixz="0.000140002" iyy="0.000912333" iyz="-3.78102e-05" izz="0.000883052"/>
    </inertial>
    <!-- Part shaft_2_parts -->
    <visual>
      <origin xyz="0.00931177 -0.00187407 -0.0491985" rpy="-3.14159 -0.785398 1.5708"/>
      <geometry>
        <mesh filename="file://$(find quadruped_control)/description/assets/shaft_2_visual.stl"/>
      </geometry>
      <material name="shaft_2_parts_material">
        <color rgba="0.603491 0.603491 0.603491 1"/>
      </material>
    </visual>
    <collision>
      <origin xyz="0.00931177 -0.00187407 -0.0491985" rpy="-3.14159 -0.785398 1.5708"/>
      <geometry>
        <mesh filename="file://$(find quadruped_control)/description/assets/shaft_2_collision.stl"/>
      </geometry>
    </collision>
  </link>
  <!-- Link shaft_3 -->
  <link name="shaft_3">
    <inertial>
      <origin xyz="0.00823991 0.00823991 -0.0152617" rpy="0 0 0"/>
      <mass value="0.0992632"/>
      <inertia ixx="3.95043e-05" ixy="-2.3154e-05" ixz="1.04189e-05" iyy="3.95043e-05" iyz="1.04189e-05" izz="6.07656e-05"/>
    </inertial>
    <!-- Part shaft_3_parts -->
    <visual>
      <origin xyz="0.00823991 0.00823991 -0.0152617" rpy="-3.14159 -0.785398 1.79769"/>
      <geometry>
        <mesh filename="file://$(find quadruped_control)/description/assets/shaft_3_visual.stl"/>
      </geometry>
      <material name="shaft_3_parts_material">
        <color rgba="0.546859 0.552826 0.557467 1"/>
      </material>
    </visual>
    <collision>
      <origin xyz="0.00823991 0.00823991 -0.0152617" rpy="-3.14159 -0.785398 1.79769"/>
      <geometry>
        <mesh filename="file://$(find quadruped_control)/description/assets/shaft_3_collision.stl"/>
      </geometry>
    </collision>
  </link>
  <!-- Joint from shaft_2 to shaft_3 -->
  <joint name="br_m3_s3" type="revolute">
    <origin xyz="0 -0 -0.0495" rpy="-0 0 -0.226893"/>
    <parent link="shaft_2"/>
    <child link="shaft_3"/>
    <axis xyz="0 0 1"/>
    <limit effort="10" velocity="12" lower="-3.14" upper="3.14"/>
    <joint_properties friction="0.5"/>
    <mimic joint="br_l4_l3" multiplier="1.0"/>
  </joint>
  <!-- Link l4_r -->
  <link name="l4_r">
    <inertial>
      <origin xyz="0.00103938 -0.0182116 -0.00554955" rpy="0 0 0"/>
      <mass value="0.0817713"/>
      <inertia ixx="0.000302906" ixy="-3.74948e-07" ixz="4.07464e-07" iyy="7.59939e-06" iyz="-6.18739e-06" izz="0.000308167"/>
    </inertial>
    <!-- Part l4_r_parts -->
    <visual>
      <origin xyz="0.00103938 -0.0182116 -0.00554955" rpy="3.14159 -0.785398 2.58309"/>
      <geometry>
        <mesh filename="file://$(find quadruped_control)/description/assets/l4_r_visual.stl"/>
      </geometry>
      <material name="l4_r_parts_material">
        <color rgba="0.712011 0.726499 0.737767 1"/>
      </material>
    </visual>
    <collision>
      <origin xyz="0.00103938 -0.0182116 -0.00554955" rpy="3.14159 -0.785398 2.58309"/>
      <geometry>
        <mesh filename="file://$(find quadruped_control)/description/assets/l4_r_collision.stl"/>
      </geometry>
    </collision>
  </link>
  <!-- Link feet -->
  <link name="feet">
    <inertial>
      <origin xyz="-5.89463e-07 5.84139e-05 0.00137833" rpy="0 0 0"/>
      <mass value="0.0122519"/>
      <inertia ixx="9.79775e-07" ixy="5e-12" ixz="6.2e-11" iyy="1.11956e-06" iyz="-3.871e-09" izz="1.18164e-06"/>
    </inertial>
    <!-- Part feet_parts -->
    <visual>
      <origin xyz="-5.89463e-07 5.84139e-05 0.00137833" rpy="1.15474 -0.384083 -2.27416"/>
      <geometry>
        <mesh filename="file://$(find quadruped_control)/description/assets/feet_visual.stl"/>
      </geometry>
      <material name="feet_parts_material">
        <color rgba="0.917647 0.917647 0.917647 1"/>
      </material>
    </visual>
    <collision>
      <origin xyz="-5.89463e-07 5.84139e-05 0.00137833" rpy="1.15474 -0.384083 -2.27416"/>
      <geometry>
        <mesh filename="file://$(find quadruped_control)/description/assets/feet_collision.stl"/>
      </geometry>
    </collision>
  </link>
  <!-- Joint from l4_r to feet -->
  <joint name="br_feet" type="fixed">
    <origin xyz="0 -0.163 -0.004" rpy="-1.5708 -0 -0"/>
    <parent link="l4_r"/>
    <child link="feet"/>
    <axis xyz="0 0 1"/>
    <limit effort="10" velocity="12" lower="-3.14" upper="3.14"/>
    <joint_properties friction="0.5"/>
  </joint>
  <!-- Joint from shaft_2 to l4_r -->
  <joint name="br_l4_l3" type="revolute">
    <origin xyz="0.159217 -0.0159373 -0.0735" rpy="-0 0 -1.01229"/>
    <parent link="shaft_2"/>
    <child link="l4_r"/>
    <axis xyz="0 0 1"/>
    <limit effort="10" velocity="12" lower="-3.14" upper="3.14"/>
    <joint_properties friction="0.5"/>
  </joint>
  <!-- Joint from shaft to shaft_2 -->
  <joint name="br_m2_s2" type="revolute">
    <origin xyz="-0.00494975 0.00494975 -0.0735" rpy="-2.35619 1.5708 0"/>
    <parent link="shaft"/>
    <child link="shaft_2"/>
    <axis xyz="0 0 1"/>
    <limit effort="10" velocity="12" lower="-3.14" upper="3.14"/>
    <joint_properties friction="0.5"/>
  </joint>
  <!-- Joint from back_plate to shaft -->
  <joint name="br_m1_s1" type="revolute">
    <origin xyz="-0.0550383 0.114632 7.33851e-06" rpy="-1.5708 -0 3.14159"/>
    <parent link="back_plate"/>
    <child link="shaft"/>
    <axis xyz="0 0 1"/>
    <limit effort="10" velocity="12" lower="-3.14" upper="3.14"/>
    <joint_properties friction="0.5"/>
  </joint>
  <!-- Link shaft_4 -->
  <link name="shaft_4">
    <inertial>
      <origin xyz="0.00473706 0.0040862 -0.0608763" rpy="0 0 0"/>
      <mass value="0.453012"/>
      <inertia ixx="0.000546146" ixy="6.01031e-05" ixz="1.17627e-05" iyy="0.000552555" iyz="1.15907e-05" izz="0.000239462"/>
    </inertial>
    <!-- Part shaft_4_parts -->
    <visual>
      <origin xyz="0.00473706 0.0040862 -0.0608763" rpy="-1.5708 -0 -3.14159"/>
      <geometry>
        <mesh filename="file://$(find quadruped_control)/description/assets/shaft_4_visual.stl"/>
      </geometry>
      <material name="shaft_4_parts_material">
        <color rgba="0.556165 0.556165 0.556165 1"/>
      </material>
    </visual>
    <collision>
      <origin xyz="0.00473706 0.0040862 -0.0608763" rpy="-1.5708 -0 -3.14159"/>
      <geometry>
        <mesh filename="file://$(find quadruped_control)/description/assets/shaft_4_collision.stl"/>
      </geometry>
    </collision>
  </link>
  <!-- Link shaft_5 -->
  <link name="shaft_5">
    <inertial>
      <origin xyz="0.00679431 0.00633758 -0.0491985" rpy="0 0 0"/>
      <mass value="0.524841"/>
      <inertia ixx="0.000610231" ixy="-0.000236595" ixz="0.000101861" iyy="0.000743295" iyz="0.00010283" izz="0.000885096"/>
    </inertial>
    <!-- Part shaft_5_parts -->
    <visual>
      <origin xyz="0.00679431 0.00633758 -0.0491985" rpy="3.14159 0.785398 2.0944"/>
      <geometry>
        <mesh filename="file://$(find quadruped_control)/description/assets/shaft_5_visual.stl"/>
      </geometry>
      <material name="shaft_5_parts_material">
        <color rgba="0.603491 0.603491 0.603491 1"/>
      </material>
    </visual>
    <collision>
      <origin xyz="0.00679431 0.00633758 -0.0491985" rpy="3.14159 0.785398 2.0944"/>
      <geometry>
        <mesh filename="file://$(find quadruped_control)/description/assets/shaft_5_collision.stl"/>
      </geometry>
    </collision>
  </link>
  <!-- Link shaft_6 -->
  <link name="shaft_6">
    <inertial>
      <origin xyz="-0.00823991 0.00823991 -0.0152617" rpy="0 0 0"/>
      <mass value="0.0992632"/>
      <inertia ixx="3.95043e-05" ixy="2.3154e-05" ixz="-1.04189e-05" iyy="3.95043e-05" iyz="1.04189e-05" izz="6.07656e-05"/>
    </inertial>
    <!-- Part shaft_6_parts -->
    <visual>
      <origin xyz="-0.00823991 0.00823991 -0.0152617" rpy="3.14159 0.785398 -1.79769"/>
      <geometry>
        <mesh filename="file://$(find quadruped_control)/description/assets/shaft_6_visual.stl"/>
      </geometry>
      <material name="shaft_6_parts_material">
        <color rgba="0.546859 0.552826 0.557467 1"/>
      </material>
    </visual>
    <collision>
      <origin xyz="-0.00823991 0.00823991 -0.0152617" rpy="3.14159 0.785398 -1.79769"/>
      <geometry>
        <mesh filename="file://$(find quadruped_control)/description/assets/shaft_6_collision.stl"/>
      </geometry>
    </collision>
  </link>
  <!-- Joint from shaft_5 to shaft_6 -->
  <joint name="bl_m3_s3" type="revolute">
    <origin xyz="-0 0 -0.0495" rpy="-0 -0 -2.3911"/>
    <parent link="shaft_5"/>
    <child link="shaft_6"/>
    <axis xyz="0 0 1"/>
    <limit effort="10" velocity="12" lower="-3.14" upper="3.14"/>
    <joint_properties friction="0.5"/>
    <mimic joint="bl_l4_l3" multiplier="1.0"/>
  </joint>
  <!-- Link l4_l -->
  <link name="l4_l">
    <inertial>
      <origin xyz="0.00103938 0.0182116 -0.00554955" rpy="0 0 0"/>
      <mass value="0.0817713"/>
      <inertia ixx="0.000302906" ixy="3.74948e-07" ixz="4.07464e-07" iyy="7.59939e-06" iyz="6.18739e-06" izz="0.000308167"/>
    </inertial>
    <!-- Part l4_l_parts -->
    <visual>
      <origin xyz="0.00103938 0.0182116 -0.00554955" rpy="3.14159 0.785398 0.558505"/>
      <geometry>
        <mesh filename="file://$(find quadruped_control)/description/assets/l4_l_visual.stl"/>
      </geometry>
      <material name="l4_l_parts_material">
        <color rgba="0.712011 0.726499 0.737767 1"/>
      </material>
    </visual>
    <collision>
      <origin xyz="0.00103938 0.0182116 -0.00554955" rpy="3.14159 0.785398 0.558505"/>
      <geometry>
        <mesh filename="file://$(find quadruped_control)/description/assets/l4_l_collision.stl"/>
      </geometry>
    </collision>
  </link>
  <!-- Link feet_2 -->
  <link name="feet_2">
    <inertial>
      <origin xyz="-5.89463e-07 5.84139e-05 0.00137833" rpy="0 0 0"/>
      <mass value="0.0122519"/>
      <inertia ixx="9.79775e-07" ixy="5e-12" ixz="6.2e-11" iyy="1.11956e-06" iyz="-3.871e-09" izz="1.18164e-06"/>
    </inertial>
    <!-- Part feet_2_parts -->
    <visual>
      <origin xyz="-5.89463e-07 5.84139e-05 0.00137833" rpy="1.15474 0.384083 2.27416"/>
      <geometry>
        <mesh filename="file://$(find quadruped_control)/description/assets/feet_2_visual.stl"/>
      </geometry>
      <material name="feet_2_parts_material">
        <color rgba="0.917647 0.917647 0.917647 1"/>
      </material>
    </visual>
    <collision>
      <origin xyz="-5.89463e-07 5.84139e-05 0.00137833" rpy="1.15474 0.384083 2.27416"/>
      <geometry>
        <mesh filename="file://$(find quadruped_control)/description/assets/feet_2_collision.stl"/>
      </geometry>
    </collision>
  </link>
  <!-- Joint from l4_l to feet_2 -->
  <joint name="bl_feet" type="fixed">
    <origin xyz="-0 0.163 -0.004" rpy="-1.5708 -0 -3.14159"/>
    <parent link="l4_l"/>
    <child link="feet_2"/>
    <axis xyz="0 0 1"/>
    <limit effort="10" velocity="12" lower="-3.14" upper="3.14"/>
    <joint_properties friction="0.5"/>
  </joint>
  <!-- Joint from shaft_5 to l4_l -->
  <joint name="bl_l4_l3" type="revolute">
    <origin xyz="0.129917 0.0934105 -0.0735" rpy="-0 0 1.53589"/>
    <parent link="shaft_5"/>
    <child link="l4_l"/>
    <axis xyz="0 0 1"/>
    <limit effort="10" velocity="12" lower="-3.14" upper="3.14"/>
    <joint_properties friction="0.5"/>
  </joint>
  <!-- Joint from shaft_4 to shaft_5 -->
  <joint name="bl_m2_s2" type="revolute">
    <origin xyz="0.00494975 0.00494975 -0.0735" rpy="-1.5708 1.0472 -0.785398"/>
    <parent link="shaft_4"/>
    <child link="shaft_5"/>
    <axis xyz="0 0 1"/>
    <limit effort="10" velocity="12" lower="-3.14" upper="3.14"/>
    <joint_properties friction="0.5"/>
  </joint>
  <!-- Joint from back_plate to shaft_4 -->
  <joint name="bl_m1_s1" type="revolute">
    <origin xyz="0.0549617 0.114632 7.33841e-06" rpy="-1.5708 -0 -3.14159"/>
    <parent link="back_plate"/>
    <child link="shaft_4"/>
    <axis xyz="0 0 1"/>
    <limit effort="10" velocity="12" lower="-3.14" upper="3.14"/>
    <joint_properties friction="0.5"/>
  </joint>
  <!-- Link shaft_7 -->
  <link name="shaft_7">
    <inertial>
      <origin xyz="-0.00469968 -0.00412358 -0.0608763" rpy="0 0 0"/>
      <mass value="0.453012"/>
      <inertia ixx="0.000545527" ixy="6.01135e-05" ixz="-1.23936e-05" iyy="0.000553194" iyz="-1.09597e-05" izz="0.000239482"/>
    </inertial>
    <!-- Part shaft_7_parts -->
    <visual>
      <origin xyz="-0.00469968 -0.00412358 -0.0608763" rpy="1.5708 0 3.14159"/>
      <geometry>
        <mesh filename="file://$(find quadruped_control)/description/assets/shaft_7_visual.stl"/>
      </geometry>
      <material name="shaft_7_parts_material">
        <color rgba="0.556166 0.556166 0.556166 1"/>
      </material>
    </visual>
    <collision>
      <origin xyz="-0.00469968 -0.00412358 -0.0608763" rpy="1.5708 0 3.14159"/>
      <geometry>
        <mesh filename="file://$(find quadruped_control)/description/assets/shaft_7_collision.stl"/>
      </geometry>
    </collision>
  </link>
  <!-- Link shaft_8 -->
  <link name="shaft_8">
    <inertial>
      <origin xyz="0.00960955 -0.00201737 -0.0491732" rpy="0 0 0"/>
      <mass value="0.525416"/>
      <inertia ixx="0.000440202" ixy="6.05777e-05" ixz="0.000136109" iyy="0.000909648" iyz="-3.55951e-05" izz="0.000880794"/>
    </inertial>
    <!-- Part shaft_8_parts -->
    <visual>
      <origin xyz="0.00960955 -0.00201737 -0.0491732" rpy="3.14159 -0.785398 1.5708"/>
      <geometry>
        <mesh filename="file://$(find quadruped_control)/description/assets/shaft_8_visual.stl"/>
      </geometry>
      <material name="shaft_8_parts_material">
        <color rgba="0.603817 0.603817 0.603817 1"/>
      </material>
    </visual>
    <collision>
      <origin xyz="0.00960955 -0.00201737 -0.0491732" rpy="3.14159 -0.785398 1.5708"/>
      <geometry>
        <mesh filename="file://$(find quadruped_control)/description/assets/shaft_8_collision.stl"/>
      </geometry>
    </collision>
  </link>
  <!-- Link shaft_9 -->
  <link name="shaft_9">
    <inertial>
      <origin xyz="0.00823991 0.00823991 -0.0152617" rpy="0 0 0"/>
      <mass value="0.0992632"/>
      <inertia ixx="3.95043e-05" ixy="-2.3154e-05" ixz="1.04189e-05" iyy="3.95043e-05" iyz="1.04189e-05" izz="6.07656e-05"/>
    </inertial>
    <!-- Part shaft_9_parts -->
    <visual>
      <origin xyz="0.00823991 0.00823991 -0.0152617" rpy="-3.14159 -0.785398 1.79769"/>
      <geometry>
        <mesh filename="file://$(find quadruped_control)/description/assets/shaft_9_visual.stl"/>
      </geometry>
      <material name="shaft_9_parts_material">
        <color rgba="0.546859 0.552826 0.557467 1"/>
      </material>
    </visual>
    <collision>
      <origin xyz="0.00823991 0.00823991 -0.0152617" rpy="-3.14159 -0.785398 1.79769"/>
      <geometry>
        <mesh filename="file://$(find quadruped_control)/description/assets/shaft_9_collision.stl"/>
      </geometry>
    </collision>
  </link>
  <!-- Joint from shaft_8 to shaft_9 -->
  <joint name="fr_m3_s3" type="revolute">
    <origin xyz="0 -0 -0.0495" rpy="-0 -0 -0.226893"/>
    <parent link="shaft_8"/>
    <child link="shaft_9"/>
    <axis xyz="0 0 1"/>
    <limit effort="10" velocity="12" lower="-3.14" upper="3.14"/>
    <joint_properties friction="0.5"/>
    <mimic joint="fr_l4_l3" multiplier="1.0"/>
  </joint>
  <!-- Link l4_r_2 -->
  <link name="l4_r_2">
    <inertial>
      <origin xyz="0.00103938 -0.0182116 -0.00554955" rpy="0 0 0"/>
      <mass value="0.0817713"/>
      <inertia ixx="0.000302906" ixy="-3.74948e-07" ixz="4.07464e-07" iyy="7.59939e-06" iyz="-6.18739e-06" izz="0.000308167"/>
    </inertial>
    <!-- Part l4_r_2_parts -->
    <visual>
      <origin xyz="0.00103938 -0.0182116 -0.00554955" rpy="-3.14159 -0.785398 2.58309"/>
      <geometry>
        <mesh filename="file://$(find quadruped_control)/description/assets/l4_r_2_visual.stl"/>
      </geometry>
      <material name="l4_r_2_parts_material">
        <color rgba="0.712011 0.726499 0.737767 1"/>
      </material>
    </visual>
    <collision>
      <origin xyz="0.00103938 -0.0182116 -0.00554955" rpy="-3.14159 -0.785398 2.58309"/>
      <geometry>
        <mesh filename="file://$(find quadruped_control)/description/assets/l4_r_2_collision.stl"/>
      </geometry>
    </collision>
  </link>
  <!-- Link feet_3 -->
  <link name="feet_3">
    <inertial>
      <origin xyz="-5.89463e-07 5.84139e-05 0.00137833" rpy="0 0 0"/>
      <mass value="0.0122519"/>
      <inertia ixx="9.79775e-07" ixy="5e-12" ixz="6.2e-11" iyy="1.11956e-06" iyz="-3.871e-09" izz="1.18164e-06"/>
    </inertial>
    <!-- Part feet_3_parts -->
    <visual>
      <origin xyz="-5.89463e-07 5.84139e-05 0.00137833" rpy="1.15474 -0.384083 -2.27416"/>
      <geometry>
        <mesh filename="file://$(find quadruped_control)/description/assets/feet_3_visual.stl"/>
      </geometry>
      <material name="feet_3_parts_material">
        <color rgba="0.917647 0.917647 0.917647 1"/>
      </material>
    </visual>
    <collision>
      <origin xyz="-5.89463e-07 5.84139e-05 0.00137833" rpy="1.15474 -0.384083 -2.27416"/>
      <geometry>
        <mesh filename="file://$(find quadruped_control)/description/assets/feet_3_collision.stl"/>
      </geometry>
    </collision>
  </link>
  <!-- Joint from l4_r_2 to feet_3 -->
  <joint name="fr_feet" type="fixed">
    <origin xyz="-0 -0.163 -0.004" rpy="-1.5708 0 0"/>
    <parent link="l4_r_2"/>
    <child link="feet_3"/>
    <axis xyz="0 0 1"/>
    <limit effort="10" velocity="12" lower="-3.14" upper="3.14"/>
    <joint_properties friction="0.5"/>
  </joint>
  <!-- Joint from shaft_8 to l4_r_2 -->
  <joint name="fr_l4_l3" type="revolute">
    <origin xyz="0.159217 -0.0159373 -0.0735" rpy="0 -0 -1.01229"/>
    <parent link="shaft_8"/>
    <child link="l4_r_2"/>
    <axis xyz="0 0 1"/>
    <limit effort="10" velocity="12" lower="-3.14" upper="3.14"/>
    <joint_properties friction="0.5"/>
  </joint>
  <!-- Joint from shaft_7 to shaft_8 -->
  <joint name="fr_m2_s2" type="revolute">
    <origin xyz="-0.00494975 -0.00494975 -0.0735" rpy="0.785398 -1.5708 0"/>
    <parent link="shaft_7"/>
    <child link="shaft_8"/>
    <axis xyz="0 0 1"/>
    <limit effort="10" velocity="12" lower="-3.14" upper="3.14"/>
    <joint_properties friction="0.5"/>
  </joint>
  <!-- Joint from back_plate to shaft_7 -->
  <joint name="fr_m1_s1" type="revolute">
    <origin xyz="-0.0550383 -0.114368 7.33851e-06" rpy="1.5708 -0 -3.14159"/>
    <parent link="back_plate"/>
    <child link="shaft_7"/>
    <axis xyz="0 0 1"/>
    <limit effort="10" velocity="12" lower="-3.14" upper="3.14"/>
    <joint_properties friction="0.5"/>
  </joint>
  <!-- Link motor -->
  <link name="motor">
    <inertial>
      <origin xyz="0.00470307 -0.0041164 -0.0612986" rpy="0 0 0"/>
      <mass value="0.452937"/>
      <inertia ixx="0.000550142" ixy="-6.00486e-05" ixz="1.20299e-05" iyy="0.00055792" iyz="-1.12208e-05" izz="0.000239312"/>
    </inertial>
    <!-- Part motor_parts -->
    <visual>
      <origin xyz="0.00470307 -0.0041164 -0.0612986" rpy="1.5708 0 3.14159"/>
      <geometry>
        <mesh filename="file://$(find quadruped_control)/description/assets/motor_visual.stl"/>
      </geometry>
      <material name="motor_parts_material">
        <color rgba="0.556109 0.556109 0.556109 1"/>
      </material>
    </visual>
    <collision>
      <origin xyz="0.00470307 -0.0041164 -0.0612986" rpy="1.5708 0 3.14159"/>
      <geometry>
        <mesh filename="file://$(find quadruped_control)/description/assets/motor_collision.stl"/>
      </geometry>
    </collision>
  </link>
  <!-- Link motor_2 -->
  <link name="motor_2">
    <inertial>
      <origin xyz="-0.00935089 -0.00223441 -0.0491732" rpy="0 0 0"/>
      <mass value="0.525416"/>
      <inertia ixx="0.000439621" ixy="-5.98025e-05" ixz="-0.000135732" iyy="0.000912321" iyz="-3.59112e-05" izz="0.000882886"/>
    </inertial>
    <!-- Part motor_2_parts -->
    <visual>
      <origin xyz="-0.00935089 -0.00223441 -0.0491732" rpy="-3.14159 0.785398 -1.5708"/>
      <geometry>
        <mesh filename="file://$(find quadruped_control)/description/assets/motor_2_visual.stl"/>
      </geometry>
      <material name="motor_2_parts_material">
        <color rgba="0.603817 0.603817 0.603817 1"/>
      </material>
    </visual>
    <collision>
      <origin xyz="-0.00935089 -0.00223441 -0.0491732" rpy="-3.14159 0.785398 -1.5708"/>
      <geometry>
        <mesh filename="file://$(find quadruped_control)/description/assets/motor_2_collision.stl"/>
      </geometry>
    </collision>
  </link>
  <!-- Link shaft_10 -->
  <link name="shaft_10">
    <inertial>
      <origin xyz="-0.00823991 0.00823991 -0.0152617" rpy="0 0 0"/>
      <mass value="0.0992632"/>
      <inertia ixx="3.95043e-05" ixy="2.3154e-05" ixz="-1.04189e-05" iyy="3.95043e-05" iyz="1.04189e-05" izz="6.07656e-05"/>
    </inertial>
    <!-- Part shaft_10_parts -->
    <visual>
      <origin xyz="-0.00823991 0.00823991 -0.0152617" rpy="-3.14159 0.785398 -1.79769"/>
      <geometry>
        <mesh filename="file://$(find quadruped_control)/description/assets/shaft_10_visual.stl"/>
      </geometry>
      <material name="shaft_10_parts_material">
        <color rgba="0.546859 0.552826 0.557467 1"/>
      </material>
    </visual>
    <collision>
      <origin xyz="-0.00823991 0.00823991 -0.0152617" rpy="-3.14159 0.785398 -1.79769"/>
      <geometry>
        <mesh filename="file://$(find quadruped_control)/description/assets/shaft_10_collision.stl"/>
      </geometry>
    </collision>
  </link>
  <!-- Joint from motor_2 to shaft_10 -->
  <joint name="fl_m3_s3" type="revolute">
    <origin xyz="0 0 -0.0495" rpy="-0 0 0.226893"/>
    <parent link="motor_2"/>
    <child link="shaft_10"/>
    <axis xyz="0 0 1"/>
    <limit effort="10" velocity="12" lower="-3.14" upper="3.14"/>
    <joint_properties friction="0.5"/>
    <mimic joint="fl_l4_l3" multiplier="1.0"/>
  </joint>
  <!-- Link l4_l_2 -->
  <link name="l4_l_2">
    <inertial>
      <origin xyz="0.00103938 0.0182116 -0.00554955" rpy="0 0 0"/>
      <mass value="0.0817713"/>
      <inertia ixx="0.000302906" ixy="3.74948e-07" ixz="4.07464e-07" iyy="7.59939e-06" iyz="6.18739e-06" izz="0.000308167"/>
    </inertial>
    <!-- Part l4_l_2_parts -->
    <visual>
      <origin xyz="0.00103938 0.0182116 -0.00554955" rpy="-3.14159 0.785398 0.558505"/>
      <geometry>
        <mesh filename="file://$(find quadruped_control)/description/assets/l4_l_2_visual.stl"/>
      </geometry>
      <material name="l4_l_2_parts_material">
        <color rgba="0.712011 0.726499 0.737767 1"/>
      </material>
    </visual>
    <collision>
      <origin xyz="0.00103938 0.0182116 -0.00554955" rpy="-3.14159 0.785398 0.558505"/>
      <geometry>
        <mesh filename="file://$(find quadruped_control)/description/assets/l4_l_2_collision.stl"/>
      </geometry>
    </collision>
  </link>
  <!-- Link feet_4 -->
  <link name="feet_4">
    <inertial>
      <origin xyz="-5.89463e-07 5.84139e-05 0.00137833" rpy="0 0 0"/>
      <mass value="0.0122519"/>
      <inertia ixx="9.79775e-07" ixy="5e-12" ixz="6.2e-11" iyy="1.11956e-06" iyz="-3.871e-09" izz="1.18164e-06"/>
    </inertial>
    <!-- Part feet_4_parts -->
    <visual>
      <origin xyz="-5.89463e-07 5.84139e-05 0.00137833" rpy="1.15474 0.384083 2.27416"/>
      <geometry>
        <mesh filename="file://$(find quadruped_control)/description/assets/feet_4_visual.stl"/>
      </geometry>
      <material name="feet_4_parts_material">
        <color rgba="0.917647 0.917647 0.917647 1"/>
      </material>
    </visual>
    <collision>
      <origin xyz="-5.89463e-07 5.84139e-05 0.00137833" rpy="1.15474 0.384083 2.27416"/>
      <geometry>
        <mesh filename="file://$(find quadruped_control)/description/assets/feet_4_collision.stl"/>
      </geometry>
    </collision>
  </link>
  <!-- Joint from l4_l_2 to feet_4 -->
  <joint name="fl_feet" type="fixed">
    <origin xyz="0 0.163 -0.004" rpy="-1.5708 0 3.14159"/>
    <parent link="l4_l_2"/>
    <child link="feet_4"/>
    <axis xyz="0 0 1"/>
    <limit effort="10" velocity="12" lower="-3.14" upper="3.14"/>
    <joint_properties friction="0.5"/>
  </joint>
  <!-- Joint from motor_2 to l4_l_2 -->
  <joint name="fl_l4_l3" type="revolute">
    <origin xyz="-0.159217 -0.0159373 -0.0735" rpy="0 -0 -2.1293"/>
    <parent link="motor_2"/>
    <child link="l4_l_2"/>
    <axis xyz="0 0 1"/>
    <limit effort="10" velocity="12" lower="-3.14" upper="3.14"/>
    <joint_properties friction="0.5"/>
  </joint>
  <!-- Joint from motor to motor_2 -->
  <joint name="fl_m2_s2" type="revolute">
    <origin xyz="0.00494975 -0.00494975 -0.0735" rpy="0.785398 1.5708 0"/>
    <parent link="motor"/>
    <child link="motor_2"/>
    <axis xyz="0 0 1"/>
    <limit effort="10" velocity="12" lower="-3.14" upper="3.14"/>
    <joint_properties friction="0.5"/>
  </joint>
  <!-- Joint from back_plate to motor -->
  <joint name="fl_m1_s1" type="revolute">
    <origin xyz="0.0549617 -0.114368 7.33841e-06" rpy="1.5708 -0 -3.14159"/>
    <parent link="back_plate"/>
    <child link="motor"/>
    <axis xyz="0 0 1"/>
    <limit effort="10" velocity="12" lower="-3.14" upper="3.14"/>
    <joint_properties friction="0.5"/>
  </joint>

  <ros2_control name="MujocoSystem" type="system">
    <hardware>
      <plugin>mujoco_ros2_control/MujocoSystemInterface</plugin>
      <param name="mujoco_model">$(find quadruped_control)/description/robot.xml</param>
      <param name="odom_free_joint_name">back_plate_freejoint</param>
      <param name="odom_topic">/odom</param>
    </hardware>
    <joint name="fl_m1_s1">
      <command_interface name="effort"/>
      <state_interface name="position"/>
      <state_interface name="velocity"/>
      <state_interface name="effort"/>
    </joint>
    <joint name="fl_m2_s2">
      <command_interface name="effort"/>
      <state_interface name="position"/>
      <state_interface name="velocity"/>
      <state_interface name="effort"/>
    </joint>
    <joint name="fl_l4_l3">
      <command_interface name="effort"/>
      <state_interface name="position"/>
      <state_interface name="velocity"/>
      <state_interface name="effort"/>
    </joint>
    <joint name="fr_m1_s1">
      <command_interface name="effort"/>
      <state_interface name="position"/>
      <state_interface name="velocity"/>
      <state_interface name="effort"/>
    </joint>
    <joint name="fr_m2_s2">
      <command_interface name="effort"/>
      <state_interface name="position"/>
      <state_interface name="velocity"/>
      <state_interface name="effort"/>
    </joint>
    <joint name="fr_l4_l3">
      <command_interface name="effort"/>
      <state_interface name="position"/>
      <state_interface name="velocity"/>
      <state_interface name="effort"/>
    </joint>
    <joint name="bl_m1_s1">
      <command_interface name="effort"/>
      <state_interface name="position"/>
      <state_interface name="velocity"/>
      <state_interface name="effort"/>
    </joint>
    <joint name="bl_m2_s2">
      <command_interface name="effort"/>
      <state_interface name="position"/>
      <state_interface name="velocity"/>
      <state_interface name="effort"/>
    </joint>
    <joint name="bl_l4_l3">
      <command_interface name="effort"/>
      <state_interface name="position"/>
      <state_interface name="velocity"/>
      <state_interface name="effort"/>
    </joint>
    <joint name="br_m1_s1">
      <command_interface name="effort"/>
      <state_interface name="position"/>
      <state_interface name="velocity"/>
      <state_interface name="effort"/>
    </joint>
    <joint name="br_m2_s2">
      <command_interface name="effort"/>
      <state_interface name="position"/>
      <state_interface name="velocity"/>
      <state_interface name="effort"/>
    </joint>
    <joint name="br_l4_l3">
      <command_interface name="effort"/>
      <state_interface name="position"/>
      <state_interface name="velocity"/>
      <state_interface name="effort"/>
    </joint>
  </ros2_control>

</robot>
