<?xml version="1.0" ?>
<!-- Generated using onshape-to-robot -->
<!-- Onshape https://cad.onshape.com/documents/bab46d1a02d1cb675f27d5f3/w/8adfe612a59991dc5461d3ee/e/70f9c16cd5f973469d7c85a0 -->
<mujoco model="robot">
  <include file="scene.xml"/>

  <compiler angle="radian" meshdir="mujoco_assets" autolimits="true"/>
  <!-- <option timestep="0.005"/> -->
  <option integrator="RK4" timestep="0.001"/>


  <default>
    <default class="robot">
      <joint frictionloss="0.00" armature="0.005"/>
      <motor forcerange="-20.0 20.0"/>
      <default class="visual">
        <geom type="mesh" contype="0" conaffinity="0" group="2"/>
      </default>
      <default class="collision">
        <geom group="3" contype="1" conaffinity="2"/>
      </default>
    </default>
  </default>
  <worldbody>
    <!-- Link back_plate -->
    <body name="back_plate" pos="0 0 0.3" quat="1 0 0 0" childclass="robot">
      <freejoint name="back_plate_freejoint"/> 
      <inertial pos="-3.82601e-05 -0.00496654 -0.00528261" mass="2.59053" fullinertia="0.0255846 0.00872593 0.0313278 -4.15339e-05 4e-12 -0.000207516"/>
      <!-- Part back_stop -->
      <geom type="mesh" class="visual" pos="-3.82602e-05 -0.0454675 -0.0499927" quat="1 0 4.64e-10 0" mesh="back_stop" material="back_stop_material"/>
      <geom type="mesh" class="collision" pos="-3.82602e-05 -0.0454675 -0.0499927" quat="1 0 4.64e-10 0" mesh="back_stop" material="back_stop_material"/>
      <!-- Part side_pipe -->
      <geom type="mesh" class="visual" pos="-0.147986 0.0936325 -0.0499927" quat="1 0 4.64e-10 0" mesh="side_pipe" material="side_pipe_material"/>
      <geom type="mesh" class="collision" pos="-0.147986 0.0936325 -0.0499927" quat="1 0 4.64e-10 0" mesh="side_pipe" material="side_pipe_material"/>
      <!-- Part side_cover -->
      <geom type="mesh" class="visual" pos="-3.82602e-05 -0.0933675 -0.0499927" quat="0 -4.64e-10 -0 -1" mesh="side_cover" material="side_cover_material"/>
      <geom type="mesh" class="collision" pos="-3.82602e-05 -0.0933675 -0.0499927" quat="0 -4.64e-10 -0 -1" mesh="side_cover" material="side_cover_material"/>
      <!-- Part back_plate -->
      <geom type="mesh" class="visual" pos="-3.82602e-05 0.0936325 -0.0499927" quat="1 -0 4.64e-10 -0" mesh="back_plate" material="back_plate_material"/>
      <geom type="mesh" class="collision" pos="-3.82602e-05 0.0936325 -0.0499927" quat="1 -0 4.64e-10 -0" mesh="back_plate" material="back_plate_material"/>
      <!-- Part battery -->
      <geom type="mesh" class="visual" pos="0.0664617 -0.0438675 -0.0209927" quat="0.707107 3.28e-10 3.28e-10 0.707107" mesh="battery" material="battery_material"/>
      <geom type="mesh" class="collision" pos="0.0664617 -0.0438675 -0.0209927" quat="0.707107 3.28e-10 3.28e-10 0.707107" mesh="battery" material="battery_material"/>
      <!-- Part motor -->
      <geom type="mesh" class="visual" pos="-0.0550383 -0.104368 7.33851e-06" quat="3.28e-10 0.707107 -0.707107 -3.28e-10" mesh="motor" material="motor_material"/>
      <geom type="mesh" class="collision" pos="-0.0550383 -0.104368 7.33851e-06" quat="3.28e-10 0.707107 -0.707107 -3.28e-10" mesh="motor" material="motor_material"/>
      <!-- Part side_cover_2 -->
      <geom type="mesh" class="visual" pos="-3.82602e-05 0.0936325 -0.0499927" quat="1 0 4.64e-10 0" mesh="side_cover" material="side_cover_material"/>
      <geom type="mesh" class="collision" pos="-3.82602e-05 0.0936325 -0.0499927" quat="1 0 4.64e-10 0" mesh="side_cover" material="side_cover_material"/>
      <!-- Part motor_2 -->
      <geom type="mesh" class="visual" pos="-0.0550383 0.104632 7.33851e-06" quat="3.28e-10 -0.707107 -0.707107 3.28e-10" mesh="motor" material="motor_material"/>
      <geom type="mesh" class="collision" pos="-0.0550383 0.104632 7.33851e-06" quat="3.28e-10 -0.707107 -0.707107 3.28e-10" mesh="motor" material="motor_material"/>
      <!-- Part motor_3 -->
      <geom type="mesh" class="visual" pos="0.0549617 -0.104368 7.33841e-06" quat="3.28e-10 0.707107 -0.707107 -3.28e-10" mesh="motor" material="motor_material"/>
      <geom type="mesh" class="collision" pos="0.0549617 -0.104368 7.33841e-06" quat="3.28e-10 0.707107 -0.707107 -3.28e-10" mesh="motor" material="motor_material"/>
      <!-- Part bot_pipe_half -->
      <geom type="mesh" class="visual" pos="-3.82602e-05 0.427632 -0.0499927" quat="0 1 -0 -4.64e-10" mesh="bot_pipe_half" material="bot_pipe_half_material"/>
      <geom type="mesh" class="collision" pos="-3.82602e-05 0.427632 -0.0499927" quat="0 1 -0 -4.64e-10" mesh="bot_pipe_half" material="bot_pipe_half_material"/>
      <!-- Part side_pipe_2 -->
      <geom type="mesh" class="visual" pos="-3.826e-05 -0.0933675 0.104007" quat="0 1 -0 -4.64e-10" mesh="side_pipe" material="side_pipe_material"/>
      <geom type="mesh" class="collision" pos="-3.826e-05 -0.0933675 0.104007" quat="0 1 -0 -4.64e-10" mesh="side_pipe" material="side_pipe_material"/>
      <!-- Part motor_4 -->
      <geom type="mesh" class="visual" pos="0.0549617 0.104632 7.33841e-06" quat="3.28e-10 -0.707107 -0.707107 3.28e-10" mesh="motor" material="motor_material"/>
      <geom type="mesh" class="collision" pos="0.0549617 0.104632 7.33841e-06" quat="3.28e-10 -0.707107 -0.707107 3.28e-10" mesh="motor" material="motor_material"/>
      <!-- Part back_stop_2 -->
      <geom type="mesh" class="visual" pos="-3.82602e-05 0.0457325 -0.0499927" quat="0 -4.64e-10 -0 -1" mesh="back_stop" material="back_stop_material"/>
      <geom type="mesh" class="collision" pos="-3.82602e-05 0.0457325 -0.0499927" quat="0 -4.64e-10 -0 -1" mesh="back_stop" material="back_stop_material"/>
      <!-- Part back_plate_2 -->
      <geom type="mesh" class="visual" pos="-3.82602e-05 -0.0933675 -0.0499927" quat="0 -4.64e-10 -0 -1" mesh="back_plate" material="back_plate_material"/>
      <geom type="mesh" class="collision" pos="-3.82602e-05 -0.0933675 -0.0499927" quat="0 -4.64e-10 -0 -1" mesh="back_plate" material="back_plate_material"/>
      <!-- Part bot_pipe_half_2 -->
      <geom type="mesh" class="visual" pos="-3.82602e-05 -0.427368 -0.0499927" quat="1 0 4.64e-10 0" mesh="bot_pipe_half" material="bot_pipe_half_material"/>
      <geom type="mesh" class="collision" pos="-3.82602e-05 -0.427368 -0.0499927" quat="1 0 4.64e-10 0" mesh="bot_pipe_half" material="bot_pipe_half_material"/>
      <!-- Part mid_clamp -->
      <geom type="mesh" class="visual" pos="-3.82602e-05 0.233232 -0.0499927" quat="1 0 4.64e-10 0" mesh="mid_clamp" material="mid_clamp_material"/>
      <geom type="mesh" class="collision" pos="-3.82602e-05 0.233232 -0.0499927" quat="1 0 4.64e-10 0" mesh="mid_clamp" material="mid_clamp_material"/>
      <!-- Part battery_2 -->
      <geom type="mesh" class="visual" pos="-0.0665383 -0.0438675 -0.0209927" quat="3.28e-10 -0.707107 -0.707107 3.28e-10" mesh="battery" material="battery_material"/>
      <geom type="mesh" class="collision" pos="-0.0665383 -0.0438675 -0.0209927" quat="3.28e-10 -0.707107 -0.707107 3.28e-10" mesh="battery" material="battery_material"/>
      <!-- Link shaft -->
      <body name="shaft" pos="-0.0550383 0.114632 7.33851e-06" quat="0 0 -0.707107 0.707107">
        <!-- Joint from back_plate to shaft -->
        <joint axis="0 0 1" name="br_m1_s1" type="hinge" range="0.0 1.22173048" frictionloss="0.00"/>
        <inertial pos="-0.00474046 0.00407901 -0.0612986" mass="0.452938" fullinertia="0.000550761 0.00055728 0.000239291 -6.00381e-05 -1.13918e-05 1.18589e-05"/>
        <!-- Part lin_1_support_br -->
        <geom type="mesh" class="visual" pos="-0.019799 0.019799 -0.0735" quat="0.653281 0.270598 -0.653281 0.270598" mesh="lin_1_support_br" material="lin_1_support_br_material"/>
        <geom type="mesh" class="collision" pos="-0.019799 0.019799 -0.0735" quat="0.653281 0.270598 -0.653281 0.270598" mesh="lin_1_support_br" material="lin_1_support_br_material"/>
        <!-- Part motor_5 -->
        <geom type="mesh" class="visual" pos="-0.0120208 0.0120208 -0.0735" quat="0.653281 -0.653281 0.270598 -0.270598" mesh="motor" material="motor_material"/>
        <geom type="mesh" class="collision" pos="-0.0120208 0.0120208 -0.0735" quat="0.653281 -0.653281 0.270598 -0.270598" mesh="motor" material="motor_material"/>
        <!-- Part shaft -->
        <geom type="mesh" class="visual" pos="0 0 0.01" quat="0.5 0.5 0.5 -0.5" mesh="shaft" material="shaft_material"/>
        <geom type="mesh" class="collision" pos="0 0 0.01" quat="0.5 0.5 0.5 -0.5" mesh="shaft" material="shaft_material"/>
        <!-- Link shaft_2 -->
        <body name="shaft_2" pos="-0.00494975 0.00494975 -0.0735" quat="0.270598 -0.653281 0.270598 0.653281">
          <!-- Joint from shaft to shaft_2 -->
          <joint axis="0 0 1" name="br_m2_s2" type="hinge" range="-1.22173048 0.0" frictionloss="0.00"/>
          <inertial pos="0.00931177 -0.00187407 -0.0491985" mass="0.524841" fullinertia="0.000439148 0.000912333 0.000883052 6.14395e-05 0.000140002 -3.78102e-05"/>
          <!-- Part bot_r -->
          <geom type="mesh" class="visual" pos="0 0 0.1275" quat="0.706434 -0.706434 0.0308436 -0.0308436" mesh="bot_r" material="bot_r_material"/>
          <geom type="mesh" class="collision" pos="0 0 0.1275" quat="0.706434 -0.706434 0.0308436 -0.0308436" mesh="bot_r" material="bot_r_material"/>
          <!-- Part top_r -->
          <geom type="mesh" class="visual" pos="0 0 0.1275" quat="0.706434 -0.706434 0.0308436 -0.0308436" mesh="top_r" material="top_r_material"/>
          <geom type="mesh" class="collision" pos="0 0 0.1275" quat="0.706434 -0.706434 0.0308436 -0.0308436" mesh="top_r" material="top_r_material"/>
          <!-- Part shaft_2 -->
          <geom type="mesh" class="visual" pos="0 0 0.01" quat="0.5 0.5 0.5 -0.5" mesh="shaft" material="shaft_material"/>
          <geom type="mesh" class="collision" pos="0 0 0.01" quat="0.5 0.5 0.5 -0.5" mesh="shaft" material="shaft_material"/>
          <!-- Part lin_2_br -->
          <geom type="mesh" class="visual" pos="0 0 0.0305" quat="0.664463 -0.664463 -0.241845 0.241845" mesh="lin_2_br" material="lin_2_br_material"/>
          <geom type="mesh" class="collision" pos="0 0 0.0305" quat="0.664463 -0.664463 -0.241845 0.241845" mesh="lin_2_br" material="lin_2_br_material"/>
          <!-- Part motor_6 -->
          <geom type="mesh" class="visual" pos="0 -0 -0.0395" quat="0.640856 0.298836 0.640856 -0.298836" mesh="motor" material="motor_material"/>
          <geom type="mesh" class="collision" pos="0 -0 -0.0395" quat="0.640856 0.298836 0.640856 -0.298836" mesh="motor" material="motor_material"/>
          <!-- Link shaft_3 -->
          <body name="shaft_3" pos="0 -0 -0.0495" quat="0.993572 -0 0 -0.113203">
            <!-- Joint from shaft_2 to shaft_3 -->
            <joint axis="0 0 1" name="br_m3_s3" type="hinge" range="0.0 1.22173048" frictionloss="0.00"/>
            <inertial pos="0.00823991 0.00823991 -0.0152617" mass="0.0992632" fullinertia="3.95043e-05 3.95043e-05 6.07656e-05 -2.3154e-05 1.04189e-05 1.04189e-05"/>
            <!-- Part bearing -->
            <geom type="mesh" class="visual" pos="0.0388909 0.0388909 -0.032" quat="0.653281 -0.653281 0.270598 -0.270598" mesh="bearing" material="bearing_material"/>
            <geom type="mesh" class="collision" pos="0.0388909 0.0388909 -0.032" quat="0.653281 -0.653281 0.270598 -0.270598" mesh="bearing" material="bearing_material"/>
            <!-- Part shaft_3 -->
            <geom type="mesh" class="visual" pos="0 0 0.01" quat="0.5 0.5 0.5 -0.5" mesh="shaft" material="shaft_material"/>
            <geom type="mesh" class="collision" pos="0 0 0.01" quat="0.5 0.5 0.5 -0.5" mesh="shaft" material="shaft_material"/>
            <!-- Part mid_r -->
            <geom type="mesh" class="visual" pos="-0 -0 0.186" quat="0.653281 -0.653281 0.270598 -0.270598" mesh="mid_r" material="mid_r_material"/>
            <geom type="mesh" class="collision" pos="-0 -0 0.186" quat="0.653281 -0.653281 0.270598 -0.270598" mesh="mid_r" material="mid_r_material"/>
          </body>
          <!-- Link l4_r -->
          <body name="l4_r" pos="0.159217 -0.0159373 -0.0735" quat="0.87462 -0 0 -0.48481">
            <!-- Joint from shaft_2 to l4_r -->
            <joint axis="0 0 1" name="br_l4_l3" type="hinge" range="0.0 1.22173048" frictionloss="0.00"/>
            <inertial pos="0.00103938 -0.0182116 -0.00554955" mass="0.0817713" fullinertia="0.000302906 7.59939e-06 0.000308167 -3.74948e-07 4.07464e-07 -6.18739e-06"/>
            <!-- Part l4_r -->
            <geom type="mesh" class="visual" pos="-0.16 0.002 0.192" quat="0.707107 -0.707107 0 -0" mesh="l4_r" material="l4_r_material"/>
            <geom type="mesh" class="collision" pos="-0.16 0.002 0.192" quat="0.707107 -0.707107 0 -0" mesh="l4_r" material="l4_r_material"/>
            <!-- Part bearing_2 -->
            <geom type="mesh" class="visual" pos="0 0.055 -0.008" quat="0.707107 -0.707107 0 0" mesh="bearing" material="bearing_material"/>
            <geom type="mesh" class="collision" pos="0 0.055 -0.008" quat="0.707107 -0.707107 0 0" mesh="bearing" material="bearing_material"/>
            <!-- Part bearing_3 -->
            <geom type="mesh" class="visual" pos="0 0 -0.008" quat="0.707107 -0.707107 0 0" mesh="bearing" material="bearing_material"/>
            <geom type="mesh" class="collision" pos="0 0 -0.008" quat="0.707107 -0.707107 0 0" mesh="bearing" material="bearing_material"/>
            <!-- Link feet -->
            <body name="feet" pos="0 -0.163 -0.004" quat="0.707107 -0.707107 0 0">
              <!-- Joint from l4_r to feet -->
              <!-- Joint is "fixed", skipping it -->
              <inertial pos="-5.89463e-07 5.84139e-05 0.00137833" mass="0.0122519" fullinertia="9.79775e-07 1.11956e-06 1.18164e-06 5e-12 6.2e-11 -3.871e-09"/>
              <!-- Part feet -->
              <geom type="mesh" class="visual" pos="0.200014 0.035 0.203" quat="1 0 0 0" mesh="feet" material="feet_material"/>
              <geom type="mesh" class="collision" pos="0.200014 0.035 0.203" quat="1 0 0 0" mesh="feet" material="feet_material"/>
            </body>
          </body>
        </body>
      </body>
      <!-- Link shaft_4 -->
      <body name="shaft_4" pos="0.0549617 0.114632 7.33841e-06" quat="0 0 -0.707107 0.707107">
        <!-- Joint from back_plate to shaft_4 -->
        <joint axis="0 0 1" name="bl_m1_s1" type="hinge" range="-1.22173048 0.0" frictionloss="0.00"/>
        <inertial pos="0.00473706 0.0040862 -0.0608763" mass="0.453012" fullinertia="0.000546146 0.000552555 0.000239462 6.01031e-05 1.17627e-05 1.15907e-05"/>
        <!-- Part shaft_4 -->
        <geom type="mesh" class="visual" pos="0 0 0.01" quat="0.5 0.5 0.5 -0.5" mesh="shaft" material="shaft_material"/>
        <geom type="mesh" class="collision" pos="0 0 0.01" quat="0.5 0.5 0.5 -0.5" mesh="shaft" material="shaft_material"/>
        <!-- Part motor_7 -->
        <geom type="mesh" class="visual" pos="0.0120208 0.0120208 -0.0735" quat="0.270598 0.270598 -0.653281 -0.653281" mesh="motor" material="motor_material"/>
        <geom type="mesh" class="collision" pos="0.0120208 0.0120208 -0.0735" quat="0.270598 0.270598 -0.653281 -0.653281" mesh="motor" material="motor_material"/>
        <!-- Part lin_1_support_bl -->
        <geom type="mesh" class="visual" pos="0.0685894 0.0685894 -0.0735" quat="0.270598 0.653281 -0.270598 0.653281" mesh="lin_1_support_bl" material="lin_1_support_bl_material"/>
        <geom type="mesh" class="collision" pos="0.0685894 0.0685894 -0.0735" quat="0.270598 0.653281 -0.270598 0.653281" mesh="lin_1_support_bl" material="lin_1_support_bl_material"/>
        <!-- Link shaft_5 -->
        <body name="shaft_5" pos="0.00494975 0.00494975 -0.0735" quat="0.701057 -0.430459 0.560986 0.092296">
          <!-- Joint from shaft_4 to shaft_5 -->
          <joint axis="0 0 1" name="bl_m2_s2" type="hinge" range="0.0 1.22173048" frictionloss="0.00"/>
          <inertial pos="0.00679431 0.00633758 -0.0491985" mass="0.524841" fullinertia="0.000610231 0.000743295 0.000885096 -0.000236595 0.000101861 0.00010283"/>
          <!-- Part lin_2_bl -->
          <geom type="mesh" class="visual" pos="0 0 -0.0195" quat="0.704416 0.704416 -0.0616284 -0.0616284" mesh="lin_2_bl" material="lin_2_bl_material"/>
          <geom type="mesh" class="collision" pos="0 0 -0.0195" quat="0.704416 0.704416 -0.0616284 -0.0616284" mesh="lin_2_bl" material="lin_2_bl_material"/>
          <!-- Part top_l -->
          <geom type="mesh" class="visual" pos="0 0 -0.0725" quat="0.67438 0.67438 0.212631 0.212631" mesh="top_l" material="top_l_material"/>
          <geom type="mesh" class="collision" pos="0 0 -0.0725" quat="0.67438 0.67438 0.212631 0.212631" mesh="top_l" material="top_l_material"/>
          <!-- Part motor_8 -->
          <geom type="mesh" class="visual" pos="0 0 -0.0395" quat="0.541675 -0.454519 0.541675 0.454519" mesh="motor" material="motor_material"/>
          <geom type="mesh" class="collision" pos="0 0 -0.0395" quat="0.541675 -0.454519 0.541675 0.454519" mesh="motor" material="motor_material"/>
          <!-- Part bot_l -->
          <geom type="mesh" class="visual" pos="0 0 -0.0725" quat="0.67438 0.67438 0.212631 0.212631" mesh="bot_l" material="bot_l_material"/>
          <geom type="mesh" class="collision" pos="0 0 -0.0725" quat="0.67438 0.67438 0.212631 0.212631" mesh="bot_l" material="bot_l_material"/>
          <!-- Part shaft_5 -->
          <geom type="mesh" class="visual" pos="0 0 0.01" quat="0.5 0.5 0.5 -0.5" mesh="shaft" material="shaft_material"/>
          <geom type="mesh" class="collision" pos="0 0 0.01" quat="0.5 0.5 0.5 -0.5" mesh="shaft" material="shaft_material"/>
          <!-- Link shaft_6 -->
          <body name="shaft_6" pos="-0 0 -0.0495" quat="0.366501 -0 -0 -0.930418">
            <!-- Joint from shaft_5 to shaft_6 -->
            <joint axis="0 0 1" name="bl_m3_s3" type="hinge" range="-1.22173048 0.0" frictionloss="0.00"/>
            <inertial pos="-0.00823991 0.00823991 -0.0152617" mass="0.0992632" fullinertia="3.95043e-05 3.95043e-05 6.07656e-05 2.3154e-05 -1.04189e-05 1.04189e-05"/>
            <!-- Part bearing_4 -->
            <geom type="mesh" class="visual" pos="-0.0388909 0.0388909 -0.032" quat="0.270598 -0.270598 0.653281 -0.653281" mesh="bearing" material="bearing_material"/>
            <geom type="mesh" class="collision" pos="-0.0388909 0.0388909 -0.032" quat="0.270598 -0.270598 0.653281 -0.653281" mesh="bearing" material="bearing_material"/>
            <!-- Part shaft_6 -->
            <geom type="mesh" class="visual" pos="0 -0 0.01" quat="0.5 0.5 0.5 -0.5" mesh="shaft" material="shaft_material"/>
            <geom type="mesh" class="collision" pos="0 -0 0.01" quat="0.5 0.5 0.5 -0.5" mesh="shaft" material="shaft_material"/>
            <!-- Part mid_l -->
            <geom type="mesh" class="visual" pos="0 0 -0.014" quat="0.270598 0.270598 -0.653281 -0.653281" mesh="mid_l" material="mid_l_material"/>
            <geom type="mesh" class="collision" pos="0 0 -0.014" quat="0.270598 0.270598 -0.653281 -0.653281" mesh="mid_l" material="mid_l_material"/>
          </body>
          <!-- Link l4_l -->
          <body name="l4_l" pos="0.129917 0.0934105 -0.0735" quat="0.71934 -0 0 0.694658">
            <!-- Joint from shaft_5 to l4_l -->
            <joint axis="0 0 1" name="bl_l4_l3" type="hinge" range="-1.22173048 0.0" frictionloss="0.00"/>
            <inertial pos="0.00103938 0.0182116 -0.00554955" mass="0.0817713" fullinertia="0.000302906 7.59939e-06 0.000308167 3.74948e-07 4.07464e-07 6.18739e-06"/>
            <!-- Part bearing_5 -->
            <geom type="mesh" class="visual" pos="-0 0 -0.008" quat="0.707107 -0.707107 -0 0" mesh="bearing" material="bearing_material"/>
            <geom type="mesh" class="collision" pos="-0 0 -0.008" quat="0.707107 -0.707107 -0 0" mesh="bearing" material="bearing_material"/>
            <!-- Part bearing_6 -->
            <geom type="mesh" class="visual" pos="-0 -0.055 -0.008" quat="0.707107 -0.707107 -0 0" mesh="bearing" material="bearing_material"/>
            <geom type="mesh" class="collision" pos="-0 -0.055 -0.008" quat="0.707107 -0.707107 -0 0" mesh="bearing" material="bearing_material"/>
            <!-- Part l4_l -->
            <geom type="mesh" class="visual" pos="-0.16 -0.002 -0.008" quat="0.707107 0.707107 0 -0" mesh="l4_l" material="l4_l_material"/>
            <geom type="mesh" class="collision" pos="-0.16 -0.002 -0.008" quat="0.707107 0.707107 0 -0" mesh="l4_l" material="l4_l_material"/>
            <!-- Link feet_2 -->
            <body name="feet_2" pos="-0 0.163 -0.004" quat="0 0 -0.707107 0.707107">
              <!-- Joint from l4_l to feet_2 -->
              <!-- Joint is "fixed", skipping it -->
              <inertial pos="-5.89463e-07 5.84139e-05 0.00137833" mass="0.0122519" fullinertia="9.79775e-07 1.11956e-06 1.18164e-06 5e-12 6.2e-11 -3.871e-09"/>
              <!-- Part feet_2 -->
              <geom type="mesh" class="visual" pos="0.200014 0.035 0.203" quat="1 0 0 -0" mesh="feet" material="feet_material"/>
              <geom type="mesh" class="collision" pos="0.200014 0.035 0.203" quat="1 0 0 -0" mesh="feet" material="feet_material"/>
            </body>
          </body>
        </body>
      </body>
      <!-- Link shaft_7 -->
      <body name="shaft_7" pos="-0.0550383 -0.114368 7.33851e-06" quat="0 -0 0.707107 0.707107">
        <!-- Joint from back_plate to shaft_7 -->
        <joint axis="0 0 1" name="fr_m1_s1" type="hinge" range="-1.22173048 0.0" frictionloss="0.00"/>
        <inertial pos="-0.00469968 -0.00412358 -0.0608763" mass="0.453012" fullinertia="0.000545527 0.000553194 0.000239482 6.01135e-05 -1.23936e-05 -1.09597e-05"/>
        <!-- Part lin_1_support_fr -->
        <geom type="mesh" class="visual" pos="-0.109319 -0.109319 -0.0735" quat="0.270598 0.653281 -0.270598 0.653281" mesh="lin_1_support_fr" material="lin_1_support_fr_material"/>
        <geom type="mesh" class="collision" pos="-0.109319 -0.109319 -0.0735" quat="0.270598 0.653281 -0.270598 0.653281" mesh="lin_1_support_fr" material="lin_1_support_fr_material"/>
        <!-- Part motor_9 -->
        <geom type="mesh" class="visual" pos="-0.0120208 -0.0120208 -0.0735" quat="0.653281 0.653281 0.270598 0.270598" mesh="motor" material="motor_material"/>
        <geom type="mesh" class="collision" pos="-0.0120208 -0.0120208 -0.0735" quat="0.653281 0.653281 0.270598 0.270598" mesh="motor" material="motor_material"/>
        <!-- Part shaft_7 -->
        <geom type="mesh" class="visual" pos="0 0 0.01" quat="0.5 0.5 0.5 -0.5" mesh="shaft" material="shaft_material"/>
        <geom type="mesh" class="collision" pos="0 0 0.01" quat="0.5 0.5 0.5 -0.5" mesh="shaft" material="shaft_material"/>
        <!-- Link shaft_8 -->
        <body name="shaft_8" pos="-0.00494975 -0.00494975 -0.0735" quat="0.653281 0.270598 -0.653281 0.270598">
          <!-- Joint from shaft_7 to shaft_8 -->
          <joint axis="0 0 1" name="fr_m2_s2" type="hinge" range="-1.22173048 0.0" frictionloss="0.00"/>
          <inertial pos="0.00960955 -0.00201737 -0.0491732" mass="0.525416" fullinertia="0.000440202 0.000909648 0.000880794 6.05777e-05 0.000136109 -3.55951e-05"/>
          <!-- Part lin_2_fr -->
          <geom type="mesh" class="visual" pos="0 0 0.1305" quat="0.664463 -0.664463 -0.241845 0.241845" mesh="lin_2_fr" material="lin_2_fr_material"/>
          <geom type="mesh" class="collision" pos="0 0 0.1305" quat="0.664463 -0.664463 -0.241845 0.241845" mesh="lin_2_fr" material="lin_2_fr_material"/>
          <!-- Part motor_10 -->
          <geom type="mesh" class="visual" pos="-0 -0 -0.0395" quat="0.640856 0.298836 0.640856 -0.298836" mesh="motor" material="motor_material"/>
          <geom type="mesh" class="collision" pos="-0 -0 -0.0395" quat="0.640856 0.298836 0.640856 -0.298836" mesh="motor" material="motor_material"/>
          <!-- Part top_r_2 -->
          <geom type="mesh" class="visual" pos="-0 0 0.1275" quat="0.706434 -0.706434 0.0308436 -0.0308436" mesh="top_r" material="top_r_material"/>
          <geom type="mesh" class="collision" pos="-0 0 0.1275" quat="0.706434 -0.706434 0.0308436 -0.0308436" mesh="top_r" material="top_r_material"/>
          <!-- Part shaft_8 -->
          <geom type="mesh" class="visual" pos="0 0 0.01" quat="0.5 0.5 0.5 -0.5" mesh="shaft" material="shaft_material"/>
          <geom type="mesh" class="collision" pos="0 0 0.01" quat="0.5 0.5 0.5 -0.5" mesh="shaft" material="shaft_material"/>
          <!-- Part bot_r_2 -->
          <geom type="mesh" class="visual" pos="0 0 0.1275" quat="0.706434 -0.706434 0.0308436 -0.0308436" mesh="bot_r" material="bot_r_material"/>
          <geom type="mesh" class="collision" pos="0 0 0.1275" quat="0.706434 -0.706434 0.0308436 -0.0308436" mesh="bot_r" material="bot_r_material"/>
          <!-- Link shaft_9 -->
          <body name="shaft_9" pos="0 -0 -0.0495" quat="0.993572 -0 0 -0.113203">
            <!-- Joint from shaft_8 to shaft_9 -->
            <joint axis="0 0 1" name="fr_m3_s3" type="hinge" range="0.0 1.22173048" frictionloss="0.00"/>
            <inertial pos="0.00823991 0.00823991 -0.0152617" mass="0.0992632" fullinertia="3.95043e-05 3.95043e-05 6.07656e-05 -2.3154e-05 1.04189e-05 1.04189e-05"/>
            <!-- Part mid_r_2 -->
            <geom type="mesh" class="visual" pos="0 0 0.186" quat="0.653281 -0.653281 0.270598 -0.270598" mesh="mid_r" material="mid_r_material"/>
            <geom type="mesh" class="collision" pos="0 0 0.186" quat="0.653281 -0.653281 0.270598 -0.270598" mesh="mid_r" material="mid_r_material"/>
            <!-- Part bearing_7 -->
            <geom type="mesh" class="visual" pos="0.0388909 0.0388909 -0.032" quat="0.653281 -0.653281 0.270598 -0.270598" mesh="bearing" material="bearing_material"/>
            <geom type="mesh" class="collision" pos="0.0388909 0.0388909 -0.032" quat="0.653281 -0.653281 0.270598 -0.270598" mesh="bearing" material="bearing_material"/>
            <!-- Part shaft_9 -->
            <geom type="mesh" class="visual" pos="-0 0 0.01" quat="0.5 0.5 0.5 -0.5" mesh="shaft" material="shaft_material"/>
            <geom type="mesh" class="collision" pos="-0 0 0.01" quat="0.5 0.5 0.5 -0.5" mesh="shaft" material="shaft_material"/>
          </body>
          <!-- Link l4_r_2 -->
          <body name="l4_r_2" pos="0.159217 -0.0159373 -0.0735" quat="0.87462 -0 -0 -0.48481">
            <!-- Joint from shaft_8 to l4_r_2 -->
            <joint axis="0 0 1" name="fr_l4_l3" type="hinge" range="0.0 1.22173048" frictionloss="0.00"/>
            <inertial pos="0.00103938 -0.0182116 -0.00554955" mass="0.0817713" fullinertia="0.000302906 7.59939e-06 0.000308167 -3.74948e-07 4.07464e-07 -6.18739e-06"/>
            <!-- Part bearing_8 -->
            <geom type="mesh" class="visual" pos="-0 0 0" quat="0 0 -0.707107 -0.707107" mesh="bearing" material="bearing_material"/>
            <geom type="mesh" class="collision" pos="-0 0 0" quat="0 0 -0.707107 -0.707107" mesh="bearing" material="bearing_material"/>
            <!-- Part bearing_9 -->
            <geom type="mesh" class="visual" pos="-0 0.055 0" quat="0 -0 -0.707107 -0.707107" mesh="bearing" material="bearing_material"/>
            <geom type="mesh" class="collision" pos="-0 0.055 0" quat="0 -0 -0.707107 -0.707107" mesh="bearing" material="bearing_material"/>
            <!-- Part l4_r_2 -->
            <geom type="mesh" class="visual" pos="-0.16 0.002 0.192" quat="0.707107 -0.707107 0 0" mesh="l4_r" material="l4_r_material"/>
            <geom type="mesh" class="collision" pos="-0.16 0.002 0.192" quat="0.707107 -0.707107 0 0" mesh="l4_r" material="l4_r_material"/>
            <!-- Link feet_3 -->
            <body name="feet_3" pos="-0 -0.163 -0.004" quat="0.707107 -0.707107 0 0">
              <!-- Joint from l4_r_2 to feet_3 -->
              <!-- Joint is "fixed", skipping it -->
              <inertial pos="-5.89463e-07 5.84139e-05 0.00137833" mass="0.0122519" fullinertia="9.79775e-07 1.11956e-06 1.18164e-06 5e-12 6.2e-11 -3.871e-09"/>
              <!-- Part feet_3 -->
              <geom type="mesh" class="visual" pos="0.200014 0.035 0.203" quat="1 -0 0 -0" mesh="feet" material="feet_material"/>
              <geom type="mesh" class="collision" pos="0.200014 0.035 0.203" quat="1 -0 0 -0" mesh="feet" material="feet_material"/>
            </body>
          </body>
        </body>
      </body>
      <!-- Link motor -->
      <body name="motor" pos="0.0549617 -0.114368 7.33841e-06" quat="0 -0 0.707107 0.707107">
        <!-- Joint from back_plate to motor -->
        <joint axis="0 0 1" name="fl_m1_s1" type="hinge" range="0.0 1.22173048" frictionloss="0.00"/>
        <inertial pos="0.00470307 -0.0041164 -0.0612986" mass="0.452937" fullinertia="0.000550142 0.00055792 0.000239312 -6.00486e-05 1.20299e-05 -1.12208e-05"/>
        <!-- Part motor_11 -->
        <geom type="mesh" class="visual" pos="0.0120208 -0.0120208 -0.0735" quat="0.270598 -0.270598 -0.653281 0.653281" mesh="motor" material="motor_material"/>
        <geom type="mesh" class="collision" pos="0.0120208 -0.0120208 -0.0735" quat="0.270598 -0.270598 -0.653281 0.653281" mesh="motor" material="motor_material"/>
        <!-- Part shaft_10 -->
        <geom type="mesh" class="visual" pos="0 0 0.01" quat="0.5 0.5 0.5 -0.5" mesh="shaft" material="shaft_material"/>
        <geom type="mesh" class="collision" pos="0 0 0.01" quat="0.5 0.5 0.5 -0.5" mesh="shaft" material="shaft_material"/>
        <!-- Part lin_1_support_fl -->
        <geom type="mesh" class="visual" pos="0.158109 -0.158109 -0.0735" quat="0.653281 0.270598 -0.653281 0.270598" mesh="lin_1_support_fl" material="lin_1_support_fl_material"/>
        <geom type="mesh" class="collision" pos="0.158109 -0.158109 -0.0735" quat="0.653281 0.270598 -0.653281 0.270598" mesh="lin_1_support_fl" material="lin_1_support_fl_material"/>
        <!-- Link motor_2 -->
        <body name="motor_2" pos="0.00494975 -0.00494975 -0.0735" quat="0.653281 0.270598 0.653281 -0.270598">
          <!-- Joint from motor to motor_2 -->
          <joint axis="0 0 1" name="fl_m2_s2" type="hinge" range="0.0 1.22173048" frictionloss="0.00"/>
          <inertial pos="-0.00935089 -0.00223441 -0.0491732" mass="0.525416" fullinertia="0.000439621 0.000912321 0.000882886 -5.98025e-05 -0.000135732 -3.59112e-05"/>
          <!-- Part motor_12 -->
          <geom type="mesh" class="visual" pos="0 -0 -0.0395" quat="0.298836 0.640856 0.298836 -0.640856" mesh="motor" material="motor_material"/>
          <geom type="mesh" class="collision" pos="0 -0 -0.0395" quat="0.298836 0.640856 0.298836 -0.640856" mesh="motor" material="motor_material"/>
          <!-- Part lin_2_fl -->
          <geom type="mesh" class="visual" pos="-0 0 0.0805" quat="0.241845 0.241845 0.664463 0.664463" mesh="lin_2_fl" material="lin_2_fl_material"/>
          <geom type="mesh" class="collision" pos="-0 0 0.0805" quat="0.241845 0.241845 0.664463 0.664463" mesh="lin_2_fl" material="lin_2_fl_material"/>
          <!-- Part bot_l_2 -->
          <geom type="mesh" class="visual" pos="0 -0 -0.0725" quat="0.0308436 0.0308436 -0.706434 -0.706434" mesh="bot_l" material="bot_l_material"/>
          <geom type="mesh" class="collision" pos="0 -0 -0.0725" quat="0.0308436 0.0308436 -0.706434 -0.706434" mesh="bot_l" material="bot_l_material"/>
          <!-- Part top_l_2 -->
          <geom type="mesh" class="visual" pos="0 -0 -0.0725" quat="0.0308436 0.0308436 -0.706434 -0.706434" mesh="top_l" material="top_l_material"/>
          <geom type="mesh" class="collision" pos="0 -0 -0.0725" quat="0.0308436 0.0308436 -0.706434 -0.706434" mesh="top_l" material="top_l_material"/>
          <!-- Part shaft_11 -->
          <geom type="mesh" class="visual" pos="0 0 0.01" quat="0.5 0.5 0.5 -0.5" mesh="shaft" material="shaft_material"/>
          <geom type="mesh" class="collision" pos="0 0 0.01" quat="0.5 0.5 0.5 -0.5" mesh="shaft" material="shaft_material"/>
          <!-- Link shaft_10 -->
          <body name="shaft_10" pos="0 0 -0.0495" quat="0.993572 -0 0 0.113203">
            <!-- Joint from motor_2 to shaft_10 -->
            <joint axis="0 0 1" name="fl_m3_s3" type="hinge" range="-1.22173048 0.0" frictionloss="0.00"/>
            <inertial pos="-0.00823991 0.00823991 -0.0152617" mass="0.0992632" fullinertia="3.95043e-05 3.95043e-05 6.07656e-05 2.3154e-05 -1.04189e-05 1.04189e-05"/>
            <!-- Part mid_l_2 -->
            <geom type="mesh" class="visual" pos="0 -0 -0.014" quat="0.270598 0.270598 -0.653281 -0.653281" mesh="mid_l" material="mid_l_material"/>
            <geom type="mesh" class="collision" pos="0 -0 -0.014" quat="0.270598 0.270598 -0.653281 -0.653281" mesh="mid_l" material="mid_l_material"/>
            <!-- Part bearing_10 -->
            <geom type="mesh" class="visual" pos="-0.0388909 0.0388909 -0.024" quat="0.653281 0.653281 0.270598 0.270598" mesh="bearing" material="bearing_material"/>
            <geom type="mesh" class="collision" pos="-0.0388909 0.0388909 -0.024" quat="0.653281 0.653281 0.270598 0.270598" mesh="bearing" material="bearing_material"/>
            <!-- Part shaft_12 -->
            <geom type="mesh" class="visual" pos="0 -0 0.01" quat="0.5 0.5 0.5 -0.5" mesh="shaft" material="shaft_material"/>
            <geom type="mesh" class="collision" pos="0 -0 0.01" quat="0.5 0.5 0.5 -0.5" mesh="shaft" material="shaft_material"/>
          </body>
          <!-- Link l4_l_2 -->
          <body name="l4_l_2" pos="-0.159217 -0.0159373 -0.0735" quat="0.48481 0 -0 -0.87462">
            <!-- Joint from motor_2 to l4_l_2 -->
            <joint axis="0 0 1" name="fl_l4_l3" type="hinge" range="-1.22173048 0.0" frictionloss="0.00"/>
            <inertial pos="0.00103938 0.0182116 -0.00554955" mass="0.0817713" fullinertia="0.000302906 7.59939e-06 0.000308167 3.74948e-07 4.07464e-07 6.18739e-06"/>
            <!-- Part bearing_11 -->
            <geom type="mesh" class="visual" pos="0 -0 -0.008" quat="0.707107 -0.707107 0 0" mesh="bearing" material="bearing_material"/>
            <geom type="mesh" class="collision" pos="0 -0 -0.008" quat="0.707107 -0.707107 0 0" mesh="bearing" material="bearing_material"/>
            <!-- Part bearing_12 -->
            <geom type="mesh" class="visual" pos="-0 -0.055 0" quat="0 -0 0.707107 0.707107" mesh="bearing" material="bearing_material"/>
            <geom type="mesh" class="collision" pos="-0 -0.055 0" quat="0 -0 0.707107 0.707107" mesh="bearing" material="bearing_material"/>
            <!-- Part l4_l_2 -->
            <geom type="mesh" class="visual" pos="-0.16 -0.002 -0.008" quat="0.707107 0.707107 0 -0" mesh="l4_l" material="l4_l_material"/>
            <geom type="mesh" class="collision" pos="-0.16 -0.002 -0.008" quat="0.707107 0.707107 0 -0" mesh="l4_l" material="l4_l_material"/>
            <!-- Link feet_4 -->
            <body name="feet_4" pos="0 0.163 -0.004" quat="0 -0 -0.707107 0.707107">
              <!-- Joint from l4_l_2 to feet_4 -->
              <!-- Joint is "fixed", skipping it -->
              <inertial pos="-5.89463e-07 5.84139e-05 0.00137833" mass="0.0122519" fullinertia="9.79775e-07 1.11956e-06 1.18164e-06 5e-12 6.2e-11 -3.871e-09"/>
              <!-- Part feet_4 -->
              <geom type="mesh" class="visual" pos="0.200014 0.035 0.203" quat="1 0 0 0" mesh="feet" material="feet_material"/>
              <geom type="mesh" class="collision" pos="0.200014 0.035 0.203" quat="1 0 0 0" mesh="feet" material="feet_material"/>
            </body>
          </body>
        </body>
      </body>
    </body>
  </worldbody>
  <asset>
    <mesh file="l4_l.stl"/>
    <mesh file="l4_r.stl"/>
    <mesh file="top_l.stl"/>
    <mesh file="bot_pipe_half.stl"/>
    <mesh file="feet.stl"/>
    <mesh file="lin_1_support_bl.stl"/>
    <mesh file="lin_1_support_fr.stl"/>
    <mesh file="side_cover.stl"/>
    <mesh file="side_pipe.stl"/>
    <mesh file="top_r.stl"/>
    <mesh file="shaft.stl"/>
    <mesh file="lin_2_fl.stl"/>
    <mesh file="motor.stl"/>
    <mesh file="battery.stl"/>
    <mesh file="lin_2_fr.stl"/>
    <mesh file="bearing.stl"/>
    <mesh file="bot_l.stl"/>
    <mesh file="bot_r.stl"/>
    <mesh file="back_stop.stl"/>
    <mesh file="lin_2_bl.stl"/>
    <mesh file="mid_l.stl"/>
    <mesh file="back_plate.stl"/>
    <mesh file="lin_1_support_br.stl"/>
    <mesh file="lin_2_br.stl"/>
    <mesh file="mid_clamp.stl"/>
    <mesh file="lin_1_support_fl.stl"/>
    <mesh file="mid_r.stl"/>
    <material name="back_stop_material" rgba="1 0.756863 0.054902 1"/>
    <material name="side_pipe_material" rgba="0 0 0 1"/>
    <material name="side_cover_material" rgba="0.647059 0.647059 0.647059 1"/>
    <material name="back_plate_material" rgba="1 0.756863 0.054902 1"/>
    <material name="battery_material" rgba="0.768627 0.886275 0.952941 1"/>
    <material name="motor_material" rgba="0.498039 0.498039 0.498039 1"/>
    <material name="bot_pipe_half_material" rgba="0.972549 0.529412 0.00392157 1"/>
    <material name="mid_clamp_material" rgba="1 0.756863 0.054902 1"/>
    <material name="lin_1_support_br_material" rgba="0.901961 0.901961 0.901961 1"/>
    <material name="shaft_material" rgba="0.498039 0.498039 0.498039 1"/>
    <material name="bot_r_material" rgba="0.901961 0.901961 0.901961 1"/>
    <material name="top_r_material" rgba="0.901961 0.901961 0.901961 1"/>
    <material name="lin_2_br_material" rgba="0.901961 0.901961 0.901961 1"/>
    <material name="bearing_material" rgba="0.439216 0.47451 0.501961 1"/>
    <material name="mid_r_material" rgba="0.901961 0.901961 0.901961 1"/>
    <material name="l4_r_material" rgba="0.901961 0.901961 0.901961 1"/>
    <material name="feet_material" rgba="0.917647 0.917647 0.917647 1"/>
    <material name="lin_1_support_bl_material" rgba="0.901961 0.901961 0.901961 1"/>
    <material name="lin_2_bl_material" rgba="0.901961 0.901961 0.901961 1"/>
    <material name="top_l_material" rgba="0.901961 0.901961 0.901961 1"/>
    <material name="bot_l_material" rgba="0.901961 0.901961 0.901961 1"/>
    <material name="mid_l_material" rgba="0.901961 0.901961 0.901961 1"/>
    <material name="l4_l_material" rgba="0.901961 0.901961 0.901961 1"/>
    <material name="lin_1_support_fr_material" rgba="0.901961 0.901961 0.901961 1"/>
    <material name="lin_2_fr_material" rgba="0.901961 0.901961 0.901961 1"/>
    <material name="lin_1_support_fl_material" rgba="0.901961 0.901961 0.901961 1"/>
    <material name="lin_2_fl_material" rgba="0.901961 0.901961 0.901961 1"/>
  </asset>
  <actuator>
    <motor class="robot" name="fl_m1_s1" joint="fl_m1_s1"/>
    <motor class="robot" name="fl_m2_s2" joint="fl_m2_s2"/>
    <motor class="robot" name="fl_m3_s3" joint="fl_m3_s3"/>
    <motor class="robot" name="fl_l4_l3" joint="fl_l4_l3"/>
    <motor class="robot" name="fr_m1_s1" joint="fr_m1_s1"/>
    <motor class="robot" name="fr_m2_s2" joint="fr_m2_s2"/>
    <motor class="robot" name="fr_m3_s3" joint="fr_m3_s3"/>
    <motor class="robot" name="fr_l4_l3" joint="fr_l4_l3"/>
    <motor class="robot" name="bl_m1_s1" joint="bl_m1_s1"/>
    <motor class="robot" name="bl_m2_s2" joint="bl_m2_s2"/>
    <motor class="robot" name="bl_m3_s3" joint="bl_m3_s3"/>
    <motor class="robot" name="bl_l4_l3" joint="bl_l4_l3"/>
    <motor class="robot" name="br_m1_s1" joint="br_m1_s1"/>
    <motor class="robot" name="br_m2_s2" joint="br_m2_s2"/>
    <motor class="robot" name="br_m3_s3" joint="br_m3_s3"/>
    <motor class="robot" name="br_l4_l3" joint="br_l4_l3"/>
  </actuator>
  <equality>
    <joint joint1="br_m3_s3" joint2="br_l4_l3" polycoef="0 1.0 0 0 0"/>
    <joint joint1="bl_m3_s3" joint2="bl_l4_l3" polycoef="0 1.0 0 0 0"/>
    <joint joint1="fr_m3_s3" joint2="fr_l4_l3" polycoef="0 1.0 0 0 0"/>
    <joint joint1="fl_m3_s3" joint2="fl_l4_l3" polycoef="0 1.0 0 0 0"/>
  </equality>

  <!-- <include file="sim.xml"/> -->
</mujoco>
